Workbook

Sheet 參數
A1: 功輔回本假設（黃格可改；灰格是公式，勿覆寫）
A2: 場地按 23/31 歸功輔、8/31 歸專科週末。Katie 全職月薪 × 佔比計入功輔。小學／中學分頁會用本頁數字自動重算。
A4: 場地（17D＋17E）
A5: 月租（港元） | B5: 15000
A6: 管理費（港元／月） | B6: 4881
A7: 差餉（港元／季） | B7: 3660
A8: 差餉攤每月 | B8: =B7/3
A9: 場地每月合計 | B9: =B5+B6+B8
A10: 功輔佔日數 | B10: 23
A11: 一個月日數 | B11: 31
A12: 專科週末佔日數 | B12: =B11-B10
A13: 功輔場地（佔比分攤） | B13: =B9*B10/B11 | C13: ← 兩室功輔合計
A14: 專科週末場地 | B14: =B9*B12/B11 | C14: ← 不入功輔回本
A16: 人事
A17: Katie 全職月薪 | B17: 20000
A18: 功輔佔 Katie | B18: 0.3
A19: Katie 計入功輔 | B19: =B17*B18
A20: 資深 PT 日薪 | B20: 350
A21: 普通 PT 日薪 | B21: 210
A23: 兩室分攤場地及 Katie（合計應為 100%）
A24: 小學分攤 | B24: 0.5
A25: 中學分攤 | B25: 0.5
A26: 分攤合計（應＝100%） | B26: =B24+B25
A27: 典型月平日（掃描表用） | B27: 20
A29: 校曆（可改平日數或學費比例）
A30: 月份 | B30: 平日開放 | C30: 學費比例
A31: 9 月 | B31: 22 | C31: 1
A32: 10 月 | B32: 20 | C32: 1
A33: 11 月 | B33: 21 | C33: 1
A34: 12 月 | B34: 15 | C34: 0.75
A35: 1 月 | B35: 20 | C35: 1
A36: 2 月 | B36: 15 | C36: 0.75
A37: 3 月 | B37: 20 | C37: 1
A38: 4 月 | B38: 21 | C38: 1
A39: 5 月 | B39: 20 | C39: 1
A40: 6 月 | B40: 21 | C40: 1
A42: 學年平日合計 | B42: =SUM(B31:B40)
A43: 學費月數合計（12／2 月 75% 會計 0.75） | B43: =SUM(C31:C40)
A45: 編制規則
A46: 中學：人數>0 → ROUNDUP(人數/7,0) 位資深（1–7 一位，8–14 兩位）。 小學：人數>0 → 1 位資深，帶滿「資深每位應對」後加普通；普通人數＝ROUNDUP((人數−資深每位)/普通每位,0)。容量在小學頁黃格改。
...

Sheet 小學
A1: 小學功輔室回本
A2: 黃格可改。場地同 Katie 按「參數」頁分攤。小學編制：人數>0 → 1 位資深；超出「資深每位應對」後按「普通每位應對」加普通。 每月場地／Katie 不跟該月平日數加減；PT 跟該月平日 × 日薪。
A4: 輸入
A5: 人數 | B5: 7
A6: 月費（全費月份） | B6: 2800 | C6: 12 月／2 月自動 × 參數頁學費比例
A7: 資深每位應對學生 | B7: 4 | C7: 普通每位應對學生 | D7: 3 | E7: 人數>0 先 1 位資深；帶滿 B7 後按 D7 加普通。改呢兩格會重算編制／損益／掃描表。
A8: 編制（公式）
A9: 資深老師 | B9: =IF(B5<=0,0,1)
A10: 普通老師 | B10: =IF(OR(B5<=0,$D$7<=0),0,IF(B5<=$B$7,0,ROUNDUP((B5-$B$7)/$D$7,0)))
A11: PT 每日成本 | B11: =B9*參數!$B$20+B10*參數!$B$21
A12: 分攤場地／月 | B12: =參數!$B$13*參數!$B$24
A13: 分攤 Katie／月 | B13: =參數!$B$19*參數!$B$24
A15: 每月損益
A16: 月份 | B16: 平日 | C16: 學費比例 | D16: 場地 | E16: Katie | F16: PT | G16: 成本 | H16: 收入 | I16: 盈虧 | J16: 累計盈虧
A17: =參數!A31 | B17: =參數!B31 | C17: =參數!C31 | D17: =$B$12 | E17: =$B$13 | F17: =$B$11*B17 | G17: =D17+E17+F17 | H17: =$B$5*$B$6*C17 | I17: =H17-G17 | J17: =I17
A18: =參數!A32 | B18: =參數!B32 | C18: =參數!C32 | D18: =$B$12 | E18: =$B$13 | F18: =$B$11*B18 | G18: =D18+E18+F18 | H18: =$B$5*$B$6*C18 | I18: =H18-G18 | J18: =J17+I18
A19: =參數!A33 | B19: =參數!B33 | C19: =參數!C33 | D19: =$B$12 | E19: =$B$13 | F19: =$B$11*B19 | G19: =D19+E19+F19 | H19: =$B$5*$B$6*C19 | I19: =H19-G19 | J19: =J18+I19
A20: =參數!A34 | B20: =參數!B34 | C20: =參數!C34 | D20: =$B$12 | E20: =$B$13 | F20: =$B$11*B20 | G20: =D20+E20+F20 | H20: =$B$5*$B$6*C20 | I20: =H20-G20 | J20: =J19+I20
A21: =參數!A35 | B21: =參數!B35 | C21: =參數!C35 | D21: =$B$12 | E21: =$B$13 | F21: =$B$11*B21 | G21: =D21+E21+F21 | H21: =$B$5*$B$6*C21 | I21: =H21-G21 | J21: =J20+I21
A22: =參數!A36 | B22: =參數!B36 | C22: =參數!C36 | D22: =$B$12 | E22: =$B$13 | F22: =$B$11*B22 | G22: =D22+E22+F22 | H22: =$B$5*$B$6*C22 | I22: =H22-G22 | J22: =J21+I22
A23: =參數!A37 | B23: =參數!B37 | C23: =參數!C37 | D23: =$B$12 | E23: =$B$13 | F23: =$B$11*B23 | G23: =D23+E23+F23 | H23: =$B$5*$B$6*C23 | I23: =H23-G23 | J23: =J22+I23
A24: =參數!A38 | B24: =參數!B38 | C24: =參數!C38 | D24: =$B$12 | E24: =$B$13 | F24: =$B$11*B24 | G24: =D24+E24+F24 | H24: =$B$5*$B$6*C24 | I24: =H24-G24 | J24: =J23+I24
A25: =參數!A39 | B25: =參數!B39 | C25: =參數!C39 | D25: =$B$12 | E25: =$B$13 | F25: =$B$11*B25 | G25: =D25+E25+F25 | H25: =$B$5*$B$6*C25 | I25: =H25-G25 | J25: =J24+I25
A26: =參數!A40 | B26: =參數!B40 | C26: =參數!C40 | D26: =$B$12 | E26: =$B$13 | F26: =$B$11*B26 | G26: =D26+E26+F26 | H26: =$B$5*$B$6*C26 | I26: =H26-G26 | J26: =J25+I26
A27: 學年合計 | B27: =SUM(B17:B26) | C27: =SUM(C17:C26) | D27: =SUM(D17:D26) | E27: =SUM(E17:E26) | F27: =SUM(F17:F26) | G27: =SUM(G17:G26) | H27: =SUM(H17:H26) | I27: =SUM(I17:I26) | J27: =I27
A29: 人數掃描（典型月：用參數頁「典型月平日」，學費全費）
A30: 人數 | B30: 資深 | C30: 普通 | D30: PT每日 | E30: 典型月成本 | F30: 收入 | G30: 盈虧 | H30: 回本？
A31: 0 | B31: =IF(A31<=0,0,1) | C31: =IF(OR(A31<=0,$D$7<=0),0,IF(A31<=$B$7,0,ROUNDUP((A31-$B$7)/$D$7,0))) | D31: =B31*參數!$B$20+C31*參數!$B$21 | E31: =$B$12+$B$13+D31*參數!$B$27 | F31: =A31*$B$6 | G31: =F31-E31 | H31: =IF(A31=0,"—",IF(G31>=0,"回本","未回本"))
A32: 1 | B32: =IF(A32<=0,0,1) | C32: =IF(OR(A32<=0,$D$7<=0),0,IF(A32<=$B$7,0,ROUNDUP((A32-$B$7)/$D$7,0))) | D32: =B32*參數!$B$20+C32*參數!$B$21 | E32: =$B$12+$B$13+D32*參數!$B$27 | F32: =A32*$B$6 | G32: =F32-E32 | H32: =IF(A32=0,"—",IF(G32>=0,"回本","未回本"))
A33: 2 | B33: =IF(A33<=0,0,1) | C33: =IF(OR(A33<=0,$D$7<=0),0,IF(A33<=$B$7,0,ROUNDUP((A33-$B$7)/$D$7,0))) | D33: =B33*參數!$B$20+C33*參數!$B$21 | E33: =$B$12+$B$13+D33*參數!$B$27 | F33: =A33*$B$6 | G33: =F33-E33 | H33: =IF(A33=0,"—",IF(G33>=0,"回本","未回本"))
A34: 3 | B34: =IF(A34<=0,0,1) | C34: =IF(OR(A34<=0,$D$7<=0),0,IF(A34<=$B$7,0,ROUNDUP((A34-$B$7)/$D$7,0))) | D34: =B34*參數!$B$20+C34*參數!$B$21 | E34: =$B$12+$B$13+D34*參數!$B$27 | F34: =A34*$B$6 | G34: =F34-E34 | H34: =IF(A34=0,"—",IF(G34>=0,"回本","未回本"))
A35: 4 | B35: =IF(A35<=0,0,1) | C35: =IF(OR(A35<=0,$D$7<=0),0,IF(A35<=$B$7,0,ROUNDUP((A35-$B$7)/$D$7,0))) | D35: =B35*參數!$B$20+C35*參數!$B$21 | E35: =$B$12+$B$13+D35*參數!$B$27 | F35: =A35*$B$6 | G35: =F35-E35 | H35: =IF(A35=0,"—",IF(G35>=0,"回本","未回本"))
A36: 5 | B36: =IF(A36<=0,0,1) | C36: =IF(OR(A36<=0,$D$7<=0),0,IF(A36<=$B$7,0,ROUNDUP((A36-$B$7)/$D$7,0))) | D36: =B36*參數!$B$20+C36*參數!$B$21 | E36: =$B$12+$B$13+D36*參數!$B$27 | F36: =A36*$B$6 | G36: =F36-E36 | H36: =IF(A36=0,"—",IF(G36>=0,"回本","未回本"))
A37: 6 | B37: =IF(A37<=0,0,1) | C37: =IF(OR(A37<=0,$D$7<=0),0,IF(A37<=$B$7,0,ROUNDUP((A37-$B$7)/$D$7,0))) | D37: =B37*參數!$B$20+C37*參數!$B$21 | E37: =$B$12+$B$13+D37*參數!$B$27 | F37: =A37*$B$6 | G37: =F37-E37 | H37: =IF(A37=0,"—",IF(G37>=0,"回本","未回本"))
A38: 7 | B38: =IF(A38<=0,0,1) | C38: =IF(OR(A38<=0,$D$7<=0),0,IF(A38<=$B$7,0,ROUNDUP((A38-$B$7)/$D$7,0))) | D38: =B38*參數!$B$20+C38*參數!$B$21 | E38: =$B$12+$B$13+D38*參數!$B$27 | F38: =A38*$B$6 | G38: =F38-E38 | H38: =IF(A38=0,"—",IF(G38>=0,"回本","未回本"))
A39: 8 | B39: =IF(A39<=0,0,1) | C39: =IF(OR(A39<=0,$D$7<=0),0,IF(A39<=$B$7,0,ROUNDUP((A39-$B$7)/$D$7,0))) | D39: =B39*參數!$B$20+C39*參數!$B$21 | E39: =$B$12+$B$13+D39*參數!$B$27 | F39: =A39*$B$6 | G39: =F39-E39 | H39: =IF(A39=0,"—",IF(G39>=0,"回本","未回本"))
A40: 9 | B40: =IF(A40<=0,0,1) | C40: =IF(OR(A40<=0,$D$7<=0),0,IF(A40<=$B$7,0,ROUNDUP((A40-$B$7)/$D$7,0))) | D40: =B40*參數!$B$20+C40*參數!$B$21 | E40: =$B$12+$B$13+D40*參數!$B$27 | F40: =A40*$B$6 | G40: =F40-E40 | H40: =IF(A40=0,"—",IF(G40>=0,"回本","未回本"))
A41: 10 | B41: =IF(A41<=0,0,1) | C41: =IF(OR(A41<=0,$D$7<=0),0,IF(A41<=$B$7,0,ROUNDUP((A41-$B$7)/$D$7,0))) | D41: =B41*參數!$B$20+C41*參數!$B$21 | E41: =$B$12+$B$13+D41*參數!$B$27 | F41: =A41*$B$6 | G41: =F41-E41 | H41: =IF(A41=0,"—",IF(G41>=0,"回本","未回本"))
A42: 11 | B42: =IF(A42<=0,0,1) | C42: =IF(OR(A42<=0,$D$7<=0),0,IF(A42<=$B$7,0,ROUNDUP((A42-$B$7)/$D$7,0))) | D42: =B42*參數!$B$20+C42*參數!$B$21 | E42: =$B$12+$B$13+D42*參數!$B$27 | F42: =A42*$B$6 | G42: =F42-E42 | H42: =IF(A42=0,"—",IF(G42>=0,"回本","未回本"))
... A51: 20 | B51: =IF(A51<=0,0,1) | C51: =IF(OR(A51<=0,$D$7<=0),0,IF(A51<=$B$7,0,ROUNDUP((A51-$B$7)/$D$7,0))) | D51: =B51*參數!$B$20+C51*參數!$B$21 | E51: =$B$12+$B$13+D51*參數!$B$27 | F51: =A51*$B$6 | G51: =F51-E51 | H51: =IF(A51=0,"—",IF(G51>=0,"回本","未回本"))
...

Sheet 中學
A1: 中學功輔室回本
A2: 黃格可改。場地同 Katie 按「參數」頁分攤。中學編制：人數>0 → ROUNDUP(人數/7,0) 位資深（1–7 一位，8–14 兩位）。 每月場地／Katie 不跟該月平日數加減；PT 跟該月平日 × 日薪。
A4: 輸入
A5: 人數 | B5: 7
A6: 月費（全費月份） | B6: 3200 | C6: 12 月／2 月自動 × 參數頁學費比例
A8: 編制（公式）
A9: 資深老師 | B9: =IF(B5<=0,0,ROUNDUP(B5/7,0))
A10: 普通老師 | B10: 0
A11: PT 每日成本 | B11: =B9*參數!$B$20+B10*參數!$B$21
A12: 分攤場地／月 | B12: =參數!$B$13*參數!$B$25
A13: 分攤 Katie／月 | B13: =參數!$B$19*參數!$B$25
A15: 每月損益
A16: 月份 | B16: 平日 | C16: 學費比例 | D16: 場地 | E16: Katie | F16: PT | G16: 成本 | H16: 收入 | I16: 盈虧 | J16: 累計盈虧
A17: =參數!A31 | B17: =參數!B31 | C17: =參數!C31 | D17: =$B$12 | E17: =$B$13 | F17: =$B$11*B17 | G17: =D17+E17+F17 | H17: =$B$5*$B$6*C17 | I17: =H17-G17 | J17: =I17
A18: =參數!A32 | B18: =參數!B32 | C18: =參數!C32 | D18: =$B$12 | E18: =$B$13 | F18: =$B$11*B18 | G18: =D18+E18+F18 | H18: =$B$5*$B$6*C18 | I18: =H18-G18 | J18: =J17+I18
A19: =參數!A33 | B19: =參數!B33 | C19: =參數!C33 | D19: =$B$12 | E19: =$B$13 | F19: =$B$11*B19 | G19: =D19+E19+F19 | H19: =$B$5*$B$6*C19 | I19: =H19-G19 | J19: =J18+I19
A20: =參數!A34 | B20: =參數!B34 | C20: =參數!C34 | D20: =$B$12 | E20: =$B$13 | F20: =$B$11*B20 | G20: =D20+E20+F20 | H20: =$B$5*$B$6*C20 | I20: =H20-G20 | J20: =J19+I20
A21: =參數!A35 | B21: =參數!B35 | C21: =參數!C35 | D21: =$B$12 | E21: =$B$13 | F21: =$B$11*B21 | G21: =D21+E21+F21 | H21: =$B$5*$B$6*C21 | I21: =H21-G21 | J21: =J20+I21
A22: =參數!A36 | B22: =參數!B36 | C22: =參數!C36 | D22: =$B$12 | E22: =$B$13 | F22: =$B$11*B22 | G22: =D22+E22+F22 | H22: =$B$5*$B$6*C22 | I22: =H22-G22 | J22: =J21+I22
A23: =參數!A37 | B23: =參數!B37 | C23: =參數!C37 | D23: =$B$12 | E23: =$B$13 | F23: =$B$11*B23 | G23: =D23+E23+F23 | H23: =$B$5*$B$6*C23 | I23: =H23-G23 | J23: =J22+I23
A24: =參數!A38 | B24: =參數!B38 | C24: =參數!C38 | D24: =$B$12 | E24: =$B$13 | F24: =$B$11*B24 | G24: =D24+E24+F24 | H24: =$B$5*$B$6*C24 | I24: =H24-G24 | J24: =J23+I24
A25: =參數!A39 | B25: =參數!B39 | C25: =參數!C39 | D25: =$B$12 | E25: =$B$13 | F25: =$B$11*B25 | G25: =D25+E25+F25 | H25: =$B$5*$B$6*C25 | I25: =H25-G25 | J25: =J24+I25
A26: =參數!A40 | B26: =參數!B40 | C26: =參數!C40 | D26: =$B$12 | E26: =$B$13 | F26: =$B$11*B26 | G26: =D26+E26+F26 | H26: =$B$5*$B$6*C26 | I26: =H26-G26 | J26: =J25+I26
A27: 學年合計 | B27: =SUM(B17:B26) | C27: =SUM(C17:C26) | D27: =SUM(D17:D26) | E27: =SUM(E17:E26) | F27: =SUM(F17:F26) | G27: =SUM(G17:G26) | H27: =SUM(H17:H26) | I27: =SUM(I17:I26) | J27: =I27
A29: 人數掃描（典型月：用參數頁「典型月平日」，學費全費）
A30: 人數 | B30: 資深 | C30: 普通 | D30: PT每日 | E30: 典型月成本 | F30: 收入 | G30: 盈虧 | H30: 回本？
A31: 0 | B31: =IF(A31<=0,0,ROUNDUP(A31/7,0)) | C31: 0 | D31: =B31*參數!$B$20+C31*參數!$B$21 | E31: =$B$12+$B$13+D31*參數!$B$27 | F31: =A31*$B$6 | G31: =F31-E31 | H31: =IF(A31=0,"—",IF(G31>=0,"回本","未回本"))
A32: 1 | B32: =IF(A32<=0,0,ROUNDUP(A32/7,0)) | C32: 0 | D32: =B32*參數!$B$20+C32*參數!$B$21 | E32: =$B$12+$B$13+D32*參數!$B$27 | F32: =A32*$B$6 | G32: =F32-E32 | H32: =IF(A32=0,"—",IF(G32>=0,"回本","未回本"))
A33: 2 | B33: =IF(A33<=0,0,ROUNDUP(A33/7,0)) | C33: 0 | D33: =B33*參數!$B$20+C33*參數!$B$21 | E33: =$B$12+$B$13+D33*參數!$B$27 | F33: =A33*$B$6 | G33: =F33-E33 | H33: =IF(A33=0,"—",IF(G33>=0,"回本","未回本"))
A34: 3 | B34: =IF(A34<=0,0,ROUNDUP(A34/7,0)) | C34: 0 | D34: =B34*參數!$B$20+C34*參數!$B$21 | E34: =$B$12+$B$13+D34*參數!$B$27 | F34: =A34*$B$6 | G34: =F34-E34 | H34: =IF(A34=0,"—",IF(G34>=0,"回本","未回本"))
A35: 4 | B35: =IF(A35<=0,0,ROUNDUP(A35/7,0)) | C35: 0 | D35: =B35*參數!$B$20+C35*參數!$B$21 | E35: =$B$12+$B$13+D35*參數!$B$27 | F35: =A35*$B$6 | G35: =F35-E35 | H35: =IF(A35=0,"—",IF(G35>=0,"回本","未回本"))
A36: 5 | B36: =IF(A36<=0,0,ROUNDUP(A36/7,0)) | C36: 0 | D36: =B36*參數!$B$20+C36*參數!$B$21 | E36: =$B$12+$B$13+D36*參數!$B$27 | F36: =A36*$B$6 | G36: =F36-E36 | H36: =IF(A36=0,"—",IF(G36>=0,"回本","未回本"))
A37: 6 | B37: =IF(A37<=0,0,ROUNDUP(A37/7,0)) | C37: 0 | D37: =B37*參數!$B$20+C37*參數!$B$21 | E37: =$B$12+$B$13+D37*參數!$B$27 | F37: =A37*$B$6 | G37: =F37-E37 | H37: =IF(A37=0,"—",IF(G37>=0,"回本","未回本"))
A38: 7 | B38: =IF(A38<=0,0,ROUNDUP(A38/7,0)) | C38: 0 | D38: =B38*參數!$B$20+C38*參數!$B$21 | E38: =$B$12+$B$13+D38*參數!$B$27 | F38: =A38*$B$6 | G38: =F38-E38 | H38: =IF(A38=0,"—",IF(G38>=0,"回本","未回本"))
A39: 8 | B39: =IF(A39<=0,0,ROUNDUP(A39/7,0)) | C39: 0 | D39: =B39*參數!$B$20+C39*參數!$B$21 | E39: =$B$12+$B$13+D39*參數!$B$27 | F39: =A39*$B$6 | G39: =F39-E39 | H39: =IF(A39=0,"—",IF(G39>=0,"回本","未回本"))
A40: 9 | B40: =IF(A40<=0,0,ROUNDUP(A40/7,0)) | C40: 0 | D40: =B40*參數!$B$20+C40*參數!$B$21 | E40: =$B$12+$B$13+D40*參數!$B$27 | F40: =A40*$B$6 | G40: =F40-E40 | H40: =IF(A40=0,"—",IF(G40>=0,"回本","未回本"))
A41: 10 | B41: =IF(A41<=0,0,ROUNDUP(A41/7,0)) | C41: 0 | D41: =B41*參數!$B$20+C41*參數!$B$21 | E41: =$B$12+$B$13+D41*參數!$B$27 | F41: =A41*$B$6 | G41: =F41-E41 | H41: =IF(A41=0,"—",IF(G41>=0,"回本","未回本"))
A42: 11 | B42: =IF(A42<=0,0,ROUNDUP(A42/7,0)) | C42: 0 | D42: =B42*參數!$B$20+C42*參數!$B$21 | E42: =$B$12+$B$13+D42*參數!$B$27 | F42: =A42*$B$6 | G42: =F42-E42 | H42: =IF(A42=0,"—",IF(G42>=0,"回本","未回本"))
... A51: 20 | B51: =IF(A51<=0,0,ROUNDUP(A51/7,0)) | C51: 0 | D51: =B51*參數!$B$20+C51*參數!$B$21 | E51: =$B$12+$B$13+D51*參數!$B$27 | F51: =A51*$B$6 | G51: =F51-E51 | H51: =IF(A51=0,"—",IF(G51>=0,"回本","未回本"))
A53: 現設定學年每人學費（已計 12／2 月折扣） | B53: =B6*參數!$B$43
...
